Workbook
Name UPDATE: '[1]Data Sheet'!$E$1

Sheet Assumption Sheet
B2: As per Management Guidance | N2: FY2025
M3: Q1
B4: FY2025 | C4: Q1 | D4: Q2 | F4: Q3 | G4: Q4 | H4: Forecast for FY2026 | M4: Key Driver | N4: Assumption / Analysis (One Line)
B5: Volume % growth | C5: 0.07 | D5: -0.005 | F5: 0.016 | G5: 0.021 | H5: ~7% | M5: Revenue Growth | N5: Expected to improve gradually, supported by rural recovery, festive demand, and stronger institutional activity. | P5: Rank | Q5: Initiative | R5: Major Competitors Without Comparable Offering
B6: Value growth% | C6: -0.03 | D6: -0.067 | F6: -0.078 | G6: -0.041 | H6: ~3% | M6: Volume Growth | N6: Expected to remain strong (9–11%) driven by wider distribution, rural demand, and festive season. | P6: 1 | Q6: Beautiful Homes Painting Services (600+ cities) | R6: Birla Opus, Berger Paints, Kansai Nerolac, Indigo Paints, Akzo Nobel India
B7: Distribution Network | C7: 1.65 Lakhs | D7: 1,67 lakhs | F7: 1,69 Lakhs | G7: 1,69 Lakhs | M7: Value Growth | N7: Expected to recover gradually as price hikes and an improved product mix offset the impact of earlier price cuts. | P7: 2 | Q7: Beautiful Homes Stores (74 stores, 53 cities) | R7: Birla Opus, Berger Paints, Kansai Nerolac, Indigo Paints, Akzo Nobel India
B8: Capacity Expansion | C8: +300000 KL | D8: 0 | F8: 0 | G8: 0 | M8: Pricing | N8: Moderate price increases are expected to offset raw material inflation and support profitability. | P8: 3 | Q8: Nilaya Anthology (Luxury Design Destination) | R8: Birla Opus, Berger Paints, Kansai Nerolac, Indigo Paints, Akzo Nobel India
B9: Home Décor | C9: 61 | D9: 62 | F9: 64 | G9: 72 | M9: Product Mix | N9: Expected to improve with a higher contribution from premium products, leading to better realizations. | P9: 4 | Q9: Chromacosm (5,300+ shade colour system) | R9: Birla Opus, Indigo Paints
B10: EBITDA Amrgin | C10: ~19% | D10: ~19% | F10: ~19% | G10: ~19% | H10: ~19% | M10: Rural Demand | N10: Expected to strengthen due to improved monsoon, better farm income, and recovery in Tier III & IV markets. | P10: 5 | Q10: AI Colour Visualizer & Digital Colour Consultancy (1,000+ consultation locations) | R10: Berger Paints, Birla Opus, Indigo Paints, Kansai Nerolac
M11: Premiumization | N11: Premium portfolio is expected to gain traction, supporting higher margins and revenue quality. | P11: 6 | Q11: Innovation Platform (300+ launches, 130+ patents, 14% revenue from innovation) | R11: Indigo Paints, Birla Opus
M12: Distribution Network | N12: Continued expansion of retail touchpoints is expected to drive market penetration and long-term volume growth. | P12: 7 | Q12: Backward Integration (White Cement + VAM-VAE projects) | R12: Berger Paints, Indigo Paints, Akzo Nobel India
B13: FY2026 | C13: Q1 | D13: Q2 | F13: Q3 | G13: Q4 | H13: Forecast for FY2027 | M13: Capacity Utilization | N13: Existing manufacturing capacity is sufficient to support future growth without major capacity constraints.
B14: Volume % growth | C14: 0.042 | D14: 0.109 | F14: 0.079 | G14: 0.124 | H14: ~9% | M14: Home Décor Business | N14: Expected to grow faster than the core paint business through store expansion and cross-selling opportunities.
B15: Value growth% | C15: -0.2 | D15: 0.067 | F15: 0.028 | G15: 0.102 | H15: ~5% | M15: Industrial Business | N15: Expected to deliver steady growth supported by strong automotive and industrial coatings demand. | P15: Rank | Q15: Initiative | R15: Berger Paints | S15: Kansai Nerolac | T15: Birla Opus | U15: Indigo Paints | V15: Akzo Nobel (Dulux) | W15: Competitive Position
B16: Distribution Network | C16: 1,70 lakhs | D16: 1,70 lakhs | F16: 1,70 lakhs | G16: 1,70 lakhs | H16: 1,70 lakhs | M16: International Business | N16: Growth is expected to remain moderate due to macroeconomic weakness and currency headwinds in key markets. | P16: 1 | Q16: Beautiful Homes Painting Services (600+ cities) | R16: Similar offering but much smaller | S16: Similar offering but much smaller | T16: Early stage / Limited | U16: Similar offering but much smaller | V16: Similar offering but much smaller | W16: Asian Paints is the clear market leader by scale and integration
B17: Capacity Expansion | C17: 100 | D17: 0 | H17: 700 | M17: Gross Margin | N17: Expected to remain stable at healthy levels, supported by pricing actions and sourcing efficiencies despite inflation. | P17: 2 | Q17: Beautiful Homes Stores (74 stores across 53 cities) | R17: No comparable offering | S17: No comparable offering | T17: No comparable offering | U17: No comparable offering | V17: No comparable offering | W17: Unique competitive moat | X17: 4% of Total Revenue
B18: home Décor | C18: 72 | D18: 73 | F18: 74 | G18: 74 | M18: Operating Expenses | N18: Operating expenses are expected to remain elevated in the near term due to investments in people and distribution. | P18: 3 | Q18: Nilaya Anthology (Luxury Design Destination) | R18: No comparable offering | S18: No comparable offering | T18: No comparable offering | U18: No comparable offering | V18: No comparable offering | W18: Unique competitive moat
B19: Forecasted EBITDA margin for next Quarter | C19: ~19% | D19: ~19% | F19: ~19% | G19: ~19% | H19: ~19% | M19: EBITDA Margin | N19: Expected to remain within management's target range of 18–20% as operating leverage improves. | P19: 4 | Q19: Chromacosm (5,300+ shade colour system) | R19: Similar colour system, but smaller | S19: Similar colour system, but smaller | T19: Similar colour system, but smaller | U19: Similar colour system, but smaller | V19: Similar colour system, but smaller | W19: Industry-leading scale and colour database
C20: As per CEO: single digit growth rate for both value and volume in near term | M20: Working Capital | N20: Working capital efficiency is expected to remain strong, supported by disciplined inventory and dealer management. | P20: 5 | Q20: AI Colour Visualizer & Digital Colour Consultancy (1,000+ consultation locations) | R20: Similar tool but smaller ecosystem | S20: Similar tool but smaller ecosystem | T20: Similar tool but smaller ecosystem | U20: Similar tool but smaller ecosystem | V20: Similar tool but smaller ecosystem | W20: Largest digital consultation ecosystem in India
C21: we would anticipate that the gap between the volume and the value would remain in that zone of about 4-5%. | M21: Capital Expenditure | N21: Capex is expected to normalize, with investments focused on maintenance and Home Décor expansion rather than new manufacturing capacity. | P21: 6 | Q21: Innovation Platform (300+ launches, 130+ patents, 14–17% revenue from innovation) | R21: Strong R&D but lower commercialisation | S21: Strong R&D but lower commercialisation | T21: Early-stage innovation platform | U21: Smaller innovation pipeline | V21: Strong R&D but lower commercialisation | W21: Industry leader in innovation commercialisation
C22: FY2025 | H22: FY2026 | P22: 7 | Q22: Backward Integration (White Cement + VAM + VAE projects) | R22: No comparable backward integration | S22: No comparable backward integration | T22: No comparable backward integration | U22: No comparable backward integration | V22: No comparable backward integration | W22: Unique cost-efficiency and supply-chain advantage
B23: Metric | C23: Q1 FY25 | D23: Q2 FY25 | F23: Q3 FY25 | G23: Q4 FY25 | H23: Q1 FY26 | I23: Q2 FY26 | J23: Q3 FY26 | K23: Q4 FY26
B24: Gross Margin | M24: Q2
B25: Product Mix | C25: Economy | D25: Economy | F25: Economy | G25: Economy + Premium | H25: Economy + Premium | I25: Economy + Premium | J25: Economy + PreLux | K25: Economy + PreLux | M25: Key Driver | N25: Q2 FY25 Assumption / Analysis (One Line)
B26: Pricing Approach | C26: Price Cut | D26: Price Cut | F26: Price Cut | G26: Price Cut | H26: Stable | I26: Stable | J26: Stable | K26: Price Hike | M26: Revenue Growth | N26: Revenue growth is expected to recover gradually as demand improves with better rural sentiment, government spending and wedding season, although near-term recovery remains cautious.
B27: Innovation % of revenue | C27: 0.12 | D27: 0.12 | F27: 0.12 | G27: 0.12 | H27: 0.14 | I27: 0.15 | J27: 0.16 | K27: 0.17 | M27: Volume Growth | N27: Management now expects single-digit volume growth for FY25, reflecting weaker consumer demand and extended monsoon disruptions.
B28: Inflation/ Deflation | C28: Deflation | D28: Deflation | F28: Deflation | G28: Deflation | H28: Deflation | I28: Deflation | J28: Deflation | K28: Deflation | M28: Value Growth | N28: Value growth is expected to remain under pressure in the near term due to earlier price reductions, adverse product mix and higher competitive discounting, with gradual improvement from Q3 onwards.
B29: The VAM-VAE project will bring to us very strong innovation capabilities in the market and really change the fabric of the market from the area of looking at green paints in a strong manner. That's something which we feel is a very strong catalyst for us going forward | M29: Pricing | N29: The 1.2% price hike taken in Q2 is expected to fully flow through from Q3, supporting realizations and partially offsetting raw material inflation.
M30: Product Mix | N30: Product mix is expected to improve gradually as premium products recover and demand normalizes, supporting realizations and margins.
M31: Rural Demand | N31: Rural markets continue to outperform urban markets and are expected to strengthen further following a good monsoon and higher government spending.
M32: Urban Demand | N32: Urban demand is expected to remain weak in the near term due to subdued consumer sentiment and slower discretionary spending.
M33: Premiumization | N33: Premium portfolio expansion through product innovation and upgraded offerings is expected to improve realizations over the medium term.
M34: Distribution Network | N34: Continued expansion beyond 1.67 lakh retail touchpoints is expected to support long-term market penetration and volume growth.
B35: Indian real Estate | E35: Indian GDP growth forecast | M35: Services Business | N35: Beautiful Homes Painting Services and Trusted Contractor Services continue to gain traction, strengthening customer engagement and recurring business.
H36: Indian real estate | M36: Institutional Business | N36: Projects and institutional business is expected to improve gradually as construction activity and government projects recover.
M37: Innovation | N37: Continuous product innovation and new product launches are expected to support premiumization and differentiation, with new products contributing around 12% of revenue.
M38: Capacity Expansion | N38: Brownfield capacity expansion is largely complete, while backward integration projects remain on track, reducing future supply constraints.
M39: Home Décor Business | N39: Home Décor is expected to continue outperforming the core paint business over the long term despite temporary demand softness.
M40: Industrial Business | N40: Industrial coatings are expected to remain a key growth driver, supported by healthy automotive OEM, refinish and protective coatings demand.
H41: Source: mordor intelligence | M41: International Business | N41: International business is expected to recover gradually as Bangladesh stabilizes and Nepal improves, although currency volatility remains a key risk.
...

Sheet Assumption 2
C2: Year | D2: 2016 | E2: =D2+1 -> 2017 | F2: =E2+1 -> 2018 | G2: =F2+1 -> 2019 | H2: =G2+1 -> 2020 | I2: =H2+1 -> 2021 | J2: =I2+1 -> 2022 | K2: =J2+1 -> 2023 | L2: =K2+1 -> 2024 | ... N2: =M2+1 -> 2026
C3: Decorative Segment
C4: Volume Growth | D4: 0.1 | E4: 0.06 | F4: 0.11 | G4: 0.13 | H4: 0.107 | I4: 0.125 | J4: 0.31 | K4: 0.14 | L4: 0.094 | M4: 0.025 | N4: 0.09
C6: Market Share Asian Paints | D6: out of 100 for each
C7: North India | D7: 0.48
C8: South India | D8: 0.41
C9: West India | D9: 0.33
C10: East India | D10: 0.32
C12: North
C13: Delhi NCR Region
D14: 2021 | E14: =D14+1 -> 2022 | F14: =E14+1 -> 2023 | G14: =F14+1 -> 2024 | H14: =G14+1 -> 2025 | I14: E2026
C15: NCR residential area sold(MSF) | D15: 34 | E15: 51 | F15: 72 | G15: 78 | H15: 103 | I15: 120 | J15: CAGR past 6 years
C16: y.o.y Growth | E16: =E15/D15-1 -> 0.5 | F16: =F15/E15-1 -> 0.41176471 | G16: =G15/F15-1 -> 0.083333333 | H16: =H15/G15-1 -> 0.32051282 | I16: =I15/H15-1 -> 0.16504854 | J16: =(I15/D15)^(1/5)-1 -> 0.28688715
C17: Luxury share of area sold | D17: 0.24 | H17: 0.58 | I17: H1-48%
C18: (Source: ICRA and Propequity)
C19: Note:
C20: 1. FY2026 as per ICRA its is expcted to touch 120 MSF which could be 16.5% y.o.y
C21: 2. For FY2027 growth will remain flattish as market has already achieved a good number
C22: 3.Demand is normalising after a period of exceptionally strong growth. NCR recorded very strong growth in FY2025 and is estimated to grow another 12–15% in FY2026, so the FY2027 forecast reflects a return to a more sustainable growth rate rather than a deterioration in underlying demand.
C23: South
C24: Bangluru
D25: 2021 | E25: =D25+1 -> 2022 | F25: =E25+1 -> 2023 | G25: =F25+1 -> 2024 | H25: =G25+1 -> 2025 | I25: E2026
C26: Bengluru Residential area sold (MSF) | D26: 50 | E26: 72 | F26: 80 | G26: 102 | H26: 99 | I26: 104 | J26: CAGR past 6 years
C27: y.o.y Growth | E27: =E26/D26-1 -> 0.44 | F27: =F26/E26-1 -> 0.11111111 | G27: =G26/F26-1 -> 0.275 | H27: =H26/G26-1 -> -0.029411765 | I27: =I26/H26-1 -> 0.050505051 | J27: =(I26/D26)^(1/5)-1 -> 0.15774434
C28: Shares of luxury launches | D28: 0.19 | H28: 0.37 | I28: H1-49%
C29: (Source: ICRA and Propequity)
C30: Note:
C31: 1.Demand for mid-income and luxury homes remains healthy, but the recent slowdown in luxury sales velocity means overall housing volumes are unlikely to maintain their earlier rapid growth rate.
C33: West
C34: Mumbai metropolitan
D35: 2021 | E35: =D35+1 -> 2022 | F35: =E35+1 -> 2023 | G35: =F35+1 -> 2024 | H35: =G35+1 -> 2025 | I35: E2026
C36: Mumbai Residential area sold (MSF) | D36: 150 | E36: 155 | F36: 163 | G36: 170 | H36: 160 | I36: 152 | J36: CAGR past 6 years
C37: y.o.y Growth | E37: =E36/D36-1 -> 0.033333333 | F37: =F36/E36-1 -> 0.051612903 | G37: =G36/F36-1 -> 0.042944785 | H37: =H36/G36-1 -> -0.058823529 | I37: =I36/H36-1 -> -0.05 | J37: =(I36/D36)^(1/5)-1 -> 0.0026525572
C38: Luxury share of area sold | D38: 0.31 | H38: 0.37 | I38: 9m-44%
C39: (Source: ICRA and Propequity)
C40: Note:
C41: 1. FY2027 the residential area sold is to decline 0-3%
C42: 2.MMR is more mature than the other two markets, so affordability is becoming a bigger constraint. Higher property prices are reducing absorption in the affordable and mid-income segments. Luxury demand remains resilient, but it is not sufficient to offset the weakness in the broader market, which is why ICRA expects a marginal 0–3% contraction in FY2027.

Sheet Financials>

Sheet HistoricalFS
B2: ="Historical Financial Statement"&" - "&Datasheet!$B$1 -> Historical Financial Statement - ASIAN PAINTS LTD
B3: Years | C3: 42825 | D3: 43190 | E3: 43555 | F3: 43921 | G3: 44286 | H3: 44651 | I3: 45016 | J3: 45382 | K3: 45747 | L3: 46112 | M3: LTM
A5: # | B5: Income Statement | V5: 11 | W5: =V5+1 -> 12 | X5: =W5+1 -> 13 | Y5: =X5+1 -> 14 | Z5: =Y5+1 -> 15 | AA5: =Z5+1 -> 16 | AB5: =AA5+1 -> 17 | AC5: =AB5+1 -> 18 | AD5: =AC5+1 -> 19 | ... AL5: =AK5+1 -> 27
B6: Sales | C6: =IFERROR(Datasheet!B17,0) -> 15061.99 | D6: =IFERROR(Datasheet!C17,0) -> 16824.55 | E6: =IFERROR(Datasheet!D17,0) -> 19240.13 | F6: =IFERROR(Datasheet!E17,0) -> 20211.25 | G6: =IFERROR(Datasheet!F17,0) -> 21712.79 | H6: =IFERROR(Datasheet!G17,0) -> 29101.28 | I6: =IFERROR(Datasheet!H17,0) -> 34488.59 | J6: =IFERROR(Datasheet!I17,0) -> 35494.73 | ... L6: =IFERROR(Datasheet!K17,0) -> 35583.54 | M6: =L6 -> 35583.54 | V6: 7722 | W6: 9632 | X6: 10938 | Y6: 12715 | Z6: 14183 | AA6: 15534 | AB6: 15061.99 | AC6: 16824.55 | AD6: 19240.13 | AE6: 20211.25 | AF6: 21712.79 | AG6: 29101.28 | AH6: 34488.59 | AI6: 35494.73 | AJ6: 33905.62 | AK6: 35583.54 | AL6: 35583.54
B7: Sales Growth | C7: - | D7: =D6/C6-1 -> 0.11702039 | E7: =E6/D6-1 -> 0.14357472 | F7: =F6/E6-1 -> 0.050473671 | G7: =G6/F6-1 -> 0.074292288 | H7: =H6/G6-1 -> 0.34028285 | I7: =I6/H6-1 -> 0.18512278 | J7: =J6/I6-1 -> 0.029173127 | K7: =K6/J6-1 -> -0.044770308 | L7: =L6/K6-1 -> 0.049487961 | M7: =L7 -> 0.049487961 | W7: =W6/V6-1 -> 0.24734525 | X7: =X6/W6-1 -> 0.1355897 | Y7: =Y6/X6-1 -> 0.16246114 | Z7: =Z6/Y6-1 -> 0.11545419 | AA7: =AA6/Z6-1 -> 0.095254883 | AB7: =AB6/AA6-1 -> -0.030385606 | AC7: =AC6/AB6-1 -> 0.11702039 | AD7: =AD6/AC6-1 -> 0.14357472 | ... AL7: =AL6/AK6-1 -> 0
B9: COGS | C9: =IFERROR(SUM(Datasheet!B18,Datasheet!B20:B22)-1*Datasheet!B19,0) -> 9732.66 | D9: =IFERROR(SUM(Datasheet!C18,Datasheet!C20:C22)-1*Datasheet!C19,0) -> 11194.17 | E9: =IFERROR(SUM(Datasheet!D18,Datasheet!D20:D22)-1*Datasheet!D19,0) -> 12905.81 | F9: =IFERROR(SUM(Datasheet!E18,Datasheet!E20:E22)-1*Datasheet!E19,0) -> 13158.02 | G9: =IFERROR(SUM(Datasheet!F18,Datasheet!F20:F22)-1*Datasheet!F19,0) -> 14035.07 | H9: =IFERROR(SUM(Datasheet!G18,Datasheet!G20:G22)-1*Datasheet!G19,0) -> 20590.57 | I9: =IFERROR(SUM(Datasheet!H18,Datasheet!H20:H22)-1*Datasheet!H19,0) -> 23766.7 | J9: =IFERROR(SUM(Datasheet!I18,Datasheet!I20:I22)-1*Datasheet!I19,0) -> 23009.99 | ... L9: =IFERROR(SUM(Datasheet!K18,Datasheet!K20:K22)-1*Datasheet!K19,0) -> 23489.63 | M9: =L9 -> 23489.63
B10: COGS % Sales | C10: =C9/C6 -> 0.64617358 | D10: =D9/D6 -> 0.66534736 | E10: =E9/E6 -> 0.67077561 | F10: =F9/F6 -> 0.65102455 | G10: =G9/G6 -> 0.64639643 | H10: =H9/H6 -> 0.7075486 | I10: =I9/I6 -> 0.68911776 | J10: =J9/J6 -> 0.64826497 | ... M10: =M9/M6 -> 0.66012628
B12: Gross Profit | C12: =C6-C9 -> 5329.33 | D12: =D6-D9 -> 5630.38 | E12: =E6-E9 -> 6334.32 | F12: =F6-F9 -> 7053.23 | G12: =G6-G9 -> 7677.72 | H12: =H6-H9 -> 8510.71 | I12: =I6-I9 -> 10721.89 | J12: =J6-J9 -> 12484.74 | ... M12: =M6-M9 -> 12093.91
B13: Gross Margins | C13: =C12/C6 -> 0.35382642 | D13: =D12/D6 -> 0.33465264 | E13: =E12/E6 -> 0.32922439 | F13: =F12/F6 -> 0.34897545 | G13: =G12/G6 -> 0.35360357 | H13: =H12/H6 -> 0.2924514 | I13: =I12/I6 -> 0.31088224 | J13: =J12/J6 -> 0.35173503 | ... M13: =M12/M6 -> 0.33987372
B15: Other Operating Expenses | C15: =IFERROR(SUM(Datasheet!B23:B24),0) -> 2335.57 | D15: =IFERROR(SUM(Datasheet!C23:C24),0) -> 2426.37 | E15: =IFERROR(SUM(Datasheet!D23:D24),0) -> 2569.38 | F15: =IFERROR(SUM(Datasheet!E23:E24),0) -> 2891.46 | G15: =IFERROR(SUM(Datasheet!F23:F24),0) -> 2822.12 | H15: =IFERROR(SUM(Datasheet!G23:G24),0) -> 3707.1 | I15: =IFERROR(SUM(Datasheet!H23:H24),0) -> 4462.05 | J15: =IFERROR(SUM(Datasheet!I23:I24),0) -> 4899.76 | ... L15: =IFERROR(SUM(Datasheet!K23:K24),0) -> 5394.18 | M15: =L15 -> 5394.18
B16: Oth Op Exp % Sales | C16: =C15/C6 -> 0.15506384 | D16: =D15/D6 -> 0.14421604 | E16: =E15/E6 -> 0.13354276 | F16: =F15/F6 -> 0.14306191 | G16: =G15/G6 -> 0.12997501 | H16: =H15/H6 -> 0.12738615 | I16: =I15/I6 -> 0.12937757 | J16: =J15/J6 -> 0.1380419 | ... M16: =M15/M6 -> 0.151592
B18: EBITDA | C18: =IFERROR(C12-C15,0) -> 2993.76 | D18: =IFERROR(D12-D15,0) -> 3204.01 | E18: =IFERROR(E12-E15,0) -> 3764.94 | F18: =IFERROR(F12-F15,0) -> 4161.77 | G18: =IFERROR(G12-G15,0) -> 4855.6 | H18: =IFERROR(H12-H15,0) -> 4803.61 | I18: =IFERROR(I12-I15,0) -> 6259.84 | J18: =IFERROR(J12-J15,0) -> 7584.98 | ... M18: =IFERROR(M12-M15,0) -> 6699.73
B19: EBITDA Margins | C19: =C18/C6 -> 0.19876258 | D19: =D18/D6 -> 0.19043659 | E19: =E18/E6 -> 0.19568163 | F19: =F18/F6 -> 0.20591354 | G19: =G18/G6 -> 0.22362856 | H19: =H18/H6 -> 0.16506525 | I19: =I18/I6 -> 0.18150467 | J19: =J18/J6 -> 0.21369313 | ... M19: =M18/M6 -> 0.18828172
B21: Interest | C21: =IFERROR(Datasheet!B27,0) -> 37.33 | D21: =IFERROR(Datasheet!C27,0) -> 41.47 | E21: =IFERROR(Datasheet!D27,0) -> 110.47 | F21: =IFERROR(Datasheet!E27,0) -> 102.33 | G21: =IFERROR(Datasheet!F27,0) -> 91.63 | H21: =IFERROR(Datasheet!G27,0) -> 95.41 | I21: =IFERROR(Datasheet!H27,0) -> 144.45 | J21: =IFERROR(Datasheet!I27,0) -> 205.17 | ... L21: =IFERROR(Datasheet!K27,0) -> 195.41 | M21: =L21 -> 195.41
B22: Interest % Debt | C22: =IFERROR(C21/SUM(C49,C50),0) -> 0.0077749776 | D22: =IFERROR(D21/SUM(D49,D50),0) -> 0.0077466959 | E22: =IFERROR(E21/SUM(E49,E50),0) -> 0.016297621 | F22: =IFERROR(F21/SUM(F49,F50),0) -> 0.017032829 | G22: =IFERROR(G21/SUM(G49,G50),0) -> 0.012137951 | H22: =IFERROR(H21/SUM(H49,H50),0) -> 0.010430891 | I22: =IFERROR(I21/SUM(I49,I50),0) -> 0.014759224 | J22: =IFERROR(J21/SUM(J49,J50),0) -> 0.018363889 | ... L22: =IFERROR(L21/SUM(L49,L50),0) -> 0.014863286 | M22: =L22 -> 0.014863286
B24: Depreciation | C24: =IFERROR(Datasheet!B26,0) -> 334.79 | D24: =IFERROR(Datasheet!C26,0) -> 360.47 | E24: =IFERROR(Datasheet!D26,0) -> 622.14 | F24: =IFERROR(Datasheet!E26,0) -> 780.5 | G24: =IFERROR(Datasheet!F26,0) -> 791.27 | H24: =IFERROR(Datasheet!G26,0) -> 816.36 | I24: =IFERROR(Datasheet!H26,0) -> 858.02 | J24: =IFERROR(Datasheet!I26,0) -> 853 | ... L24: =IFERROR(Datasheet!K26,0) -> 1228.85 | M24: =L24 -> 1228.85
B25: Depreciation % Gross Block | C25: =C24/'Raw FS'!E26 -> 0.085536536 | D25: =D24/'Raw FS'!F26 -> 0.07661424 | E25: =E24/'Raw FS'!G26 -> 0.076420587 | F25: =F24/'Raw FS'!H26 -> 0.094240522 | G25: =G24/'Raw FS'!I26 -> 0.094288608 | H25: =H24/'Raw FS'!J26 -> 0.095614898 | I25: =I24/'Raw FS'!K26 -> 0.088675072 | J25: =J24/'Raw FS'!L26 -> 0.073395285 | ... L25: =L24/'Raw FS'!N26 -> 0.08023309 | M25: =L25 -> 0.08023309
B27: Earnings Before Tax | C27: =IFERROR(C18-SUM(C21,C24),0) -> 2621.64 | D27: =IFERROR(D18-SUM(D21,D24),0) -> 2802.07 | E27: =IFERROR(E18-SUM(E21,E24),0) -> 3032.33 | F27: =IFERROR(F18-SUM(F21,F24),0) -> 3278.94 | G27: =IFERROR(G18-SUM(G21,G24),0) -> 3972.7 | H27: =IFERROR(H18-SUM(H21,H24),0) -> 3891.84 | I27: =IFERROR(I18-SUM(I21,I24),0) -> 5257.37 | J27: =IFERROR(J18-SUM(J21,J24),0) -> 6526.81 | ... M27: =IFERROR(M18-SUM(M21,M24),0) -> 5275.47
B28: EBT % Sales | C28: =C27/C6 -> 0.17405668 | D28: =D27/D6 -> 0.1665465 | E28: =E27/E6 -> 0.15760444 | F28: =F27/F6 -> 0.16223341 | G28: =G27/G6 -> 0.18296589 | H28: =H27/H6 -> 0.13373432 | I28: =I27/I6 -> 0.15243795 | J28: =J27/J6 -> 0.1838811 | ... M28: =M27/M6 -> 0.14825591
B30: Tax | C30: =IFERROR(Datasheet!B29,0) -> 943.29 | D30: =IFERROR(Datasheet!C29,0) -> 1040.96 | E30: =IFERROR(Datasheet!D29,0) -> 1098.06 | F30: =IFERROR(Datasheet!E29,0) -> 854.85 | G30: =IFERROR(Datasheet!F29,0) -> 1097.6 | H30: =IFERROR(Datasheet!G29,0) -> 1102.91 | I30: =IFERROR(Datasheet!H29,0) -> 1493.5 | J30: =IFERROR(Datasheet!I29,0) -> 1790.08 | ... L30: =IFERROR(Datasheet!K29,0) -> 1608.75 | M30: =L30 -> 1608.75
B31: Effective Tax Rate | C31: =C30/C27 -> 0.35980913 | D31: =D30/D27 -> 0.37149679 | E31: =E30/E27 -> 0.36211758 | F31: =F30/F27 -> 0.26070925 | G31: =G30/G27 -> 0.27628565 | H31: =H30/H27 -> 0.28339038 | I31: =I30/I27 -> 0.2840774 | J31: =J30/J27 -> 0.27426568 | ... M31: =M30/M27 -> 0.30494913
B33: Net Profit | C33: =IFERROR(C27-C30,0) -> 1678.35 | D33: =IFERROR(D27-D30,0) -> 1761.11 | E33: =IFERROR(E27-E30,0) -> 1934.27 | F33: =IFERROR(F27-F30,0) -> 2424.09 | G33: =IFERROR(G27-G30,0) -> 2875.1 | H33: =IFERROR(H27-H30,0) -> 2788.93 | I33: =IFERROR(I27-I30,0) -> 3763.87 | J33: =IFERROR(J27-J30,0) -> 4736.73 | ... M33: =IFERROR(M27-M30,0) -> 3666.72
B34: Net Margins | C34: =C33/C6 -> 0.1114295 | D34: =D33/D6 -> 0.10467501 | E34: =E33/E6 -> 0.1005331 | F34: =F33/F6 -> 0.11993766 | G34: =G33/G6 -> 0.13241504 | H34: =H33/H6 -> 0.095835303 | I34: =I33/I6 -> 0.10913377 | J34: =J33/J6 -> 0.13344882 | ... M34: =M33/M6 -> 0.1030454
B36: No. of Equity Shares | C36: =IFERROR(Datasheet!B93,0) -> 95.92 | D36: =IFERROR(Datasheet!C93,0) -> 95.92 | E36: =IFERROR(Datasheet!D93,0) -> 95.92 | F36: =IFERROR(Datasheet!E93,0) -> 95.92 | G36: =IFERROR(Datasheet!F93,0) -> 95.92 | H36: =IFERROR(Datasheet!G93,0) -> 95.92 | I36: =IFERROR(Datasheet!H93,0) -> 95.92 | J36: =IFERROR(Datasheet!I93,0) -> 95.92 | ... L36: =IFERROR(Datasheet!K93,0) -> 95.92 | M36: 29.47
B38: Earnings per share | C38: =IFERROR(C33/C36,0) -> 17.497394 | D38: =IFERROR(D33/D36,0) -> 18.360196 | E38: =IFERROR(E33/E36,0) -> 20.16545 | F38: =IFERROR(F33/F36,0) -> 25.271997 | G38: =IFERROR(G33/G36,0) -> 29.973937 | H38: =IFERROR(H33/H36,0) -> 29.075584 | I38: =IFERROR(I33/I36,0) -> 39.239679 | J38: =IFERROR(J33/J36,0) -> 49.382089 | ... L38: =IFERROR(L33/L36,0) -> 38.226856 | M38: =L38 -> 38.226856
B39: EPS Growth % | D39: =IFERROR(D38/C38-1,0) -> 0.049310335 | E39: =IFERROR(E38/D38-1,0) -> 0.098324352 | F39: =IFERROR(F38/E38-1,0) -> 0.25323249 | G39: =IFERROR(G38/F38-1,0) -> 0.18605332 | H39: =IFERROR(H38/G38-1,0) -> -0.029971131 | I39: =IFERROR(I38/H38-1,0) -> 0.34957493 | J39: =IFERROR(J38/I38-1,0) -> 0.25847333 | K39: =IFERROR(K38/J38-1,0) -> -0.29075755 | L39: =IFERROR(L38/K38-1,0) -> 0.091451381 | M39: =L39 -> 0.091451381
B41: Dividend per share | C41: =IFERROR(Datasheet!B31/Datasheet!B93,0) -> 10.300042 | D41: =IFERROR(Datasheet!C31/Datasheet!C93,0) -> 8.6999583 | E41: =IFERROR(Datasheet!D31/Datasheet!D93,0) -> 10.5 | F41: =IFERROR(Datasheet!E31/Datasheet!E93,0) -> 12 | G41: =IFERROR(Datasheet!F31/Datasheet!F93,0) -> 17.849979 | H41: =IFERROR(Datasheet!G31/Datasheet!G93,0) -> 19.150021 | I41: =IFERROR(Datasheet!H31/Datasheet!H93,0) -> 25.650021 | J41: =IFERROR(Datasheet!I31/Datasheet!I93,0) -> 33.300042 | ... L41: =IFERROR(Datasheet!K31/Datasheet!K93,0) -> 27.5 | M41: =L41 -> 27.5
B42: Dividend payout ratio | C42: =IFERROR(C41/C38,0) -> 0.58866148 | D42: =IFERROR(D41/D38,0) -> 0.47384888 | E42: =IFERROR(E41/E38,0) -> 0.52069256 | F42: =IFERROR(F41/F38,0) -> 0.47483386 | G42: =IFERROR(G41/G38,0) -> 0.59551668 | H42: =IFERROR(H41/H38,0) -> 0.65862894 | I42: =IFERROR(I41/I38,0) -> 0.65367561 | J42: =IFERROR(J41/J38,0) -> 0.6743344 | ... M42: =IFERROR(M41/M38,0) -> 0.71938954
B44: Retained Earnings | C44: =IFERROR(IF(C38>C41,1-C42,0),0) -> 0.41133852 | D44: =IFERROR(IF(D38>D41,1-D42,0),0) -> 0.52615112 | E44: =IFERROR(IF(E38>E41,1-E42,0),0) -> 0.47930744 | F44: =IFERROR(IF(F38>F41,1-F42,0),0) -> 0.52516614 | G44: =IFERROR(IF(G38>G41,1-G42,0),0) -> 0.40448332 | H44: =IFERROR(IF(H38>H41,1-H42,0),0) -> 0.34137106 | I44: =IFERROR(IF(I38>I41,1-I42,0),0) -> 0.34632439 | J44: =IFERROR(IF(J38>J41,1-J42,0),0) -> 0.3256656 | ... L44: =IFERROR(IF(L38>L41,1-L42,0),0) -> 0.28061046 | M44: =L44 -> 0.28061046
A46: # | B46: Balance Sheet
B47: Equity Share Capital | C47: =IFERROR(Datasheet!B57,0) -> 95.92 | D47: =IFERROR(Datasheet!C57,0) -> 95.92 | E47: =IFERROR(Datasheet!D57,0) -> 95.92 | F47: =IFERROR(Datasheet!E57,0) -> 95.92 | G47: =IFERROR(Datasheet!F57,0) -> 95.92 | H47: =IFERROR(Datasheet!G57,0) -> 95.92 | I47: =IFERROR(Datasheet!H57,0) -> 95.92 | J47: =IFERROR(Datasheet!I57,0) -> 95.92 | ... L47: =IFERROR(Datasheet!K57,0) -> 95.92 | M47: =L47 -> 95.92
B48: Reserves | C48: =IFERROR(Datasheet!B58,0) -> 7507.97 | D48: =IFERROR(Datasheet!C58,0) -> 8314.31 | E48: =IFERROR(Datasheet!D58,0) -> 9374.63 | F48: =IFERROR(Datasheet!E58,0) -> 10034.24 | G48: =IFERROR(Datasheet!F58,0) -> 12710.37 | H48: =IFERROR(Datasheet!G58,0) -> 13715.64 | I48: =IFERROR(Datasheet!H58,0) -> 15896.31 | J48: =IFERROR(Datasheet!I58,0) -> 18632.38 | ... L48: =IFERROR(Datasheet!K58,0) -> 21275.67 | M48: =L48 -> 21275.67
B49: Borrowings | C49: =IFERROR(Datasheet!B59,0) -> 560.34 | D49: =IFERROR(Datasheet!C59,0) -> 533.43 | E49: =IFERROR(Datasheet!D59,0) -> 1319.6 | F49: =IFERROR(Datasheet!E59,0) -> 1118.5 | G49: =IFERROR(Datasheet!F59,0) -> 1093.12 | H49: =IFERROR(Datasheet!G59,0) -> 1586.88 | I49: =IFERROR(Datasheet!H59,0) -> 1932.62 | J49: =IFERROR(Datasheet!I59,0) -> 2474.38 | ... L49: =IFERROR(Datasheet!K59,0) -> 3928.93 | M49: =L49 -> 3928.93
B50: Other Liabilities | C50: =IFERROR(Datasheet!B60,0) -> 4240.96 | D50: =IFERROR(Datasheet!C60,0) -> 4819.82 | E50: =IFERROR(Datasheet!D60,0) -> 5458.69 | F50: =IFERROR(Datasheet!E60,0) -> 4889.31 | G50: =IFERROR(Datasheet!F60,0) -> 6455.93 | H50: =IFERROR(Datasheet!G60,0) -> 7559.99 | I50: =IFERROR(Datasheet!H60,0) -> 7854.48 | J50: =IFERROR(Datasheet!I60,0) -> 8698.09 | ... L50: =IFERROR(Datasheet!K60,0) -> 9218.23 | M50: =L50 -> 9218.23
B51: Total Liabilities | C51: =SUM(C47:C50) -> 12405.19 | D51: =SUM(D47:D50) -> 13763.48 | E51: =SUM(E47:E50) -> 16248.84 | F51: =SUM(F47:F50) -> 16137.97 | G51: =SUM(G47:G50) -> 20355.34 | H51: =SUM(H47:H50) -> 22958.43 | I51: =SUM(I47:I50) -> 25779.33 | J51: =SUM(J47:J50) -> 29900.77 | ... L51: =SUM(L47:L50) -> 34518.75 | M51: =L51 -> 34518.75
B53: Fixed Assets Net Block | C53: =IFERROR(Datasheet!B62,0) -> 3303.74 | D53: =IFERROR(Datasheet!C62,0) -> 3732.24 | E53: =IFERROR(Datasheet!D62,0) -> 6496.56 | F53: =IFERROR(Datasheet!E62,0) -> 6272.31 | G53: =IFERROR(Datasheet!F62,0) -> 5858.52 | H53: =IFERROR(Datasheet!G62,0) -> 5519.06 | I53: =IFERROR(Datasheet!H62,0) -> 5770.46 | J53: =IFERROR(Datasheet!I62,0) -> 7146.62 | ... L53: =IFERROR(Datasheet!K62,0) -> 9640.28 | M53: =L53 -> 9640.28
B54: Capital Work in Progress | C54: =IFERROR(Datasheet!B63,0) -> 257.54 | D54: =IFERROR(Datasheet!C63,0) -> 1405.11 | E54: =IFERROR(Datasheet!D63,0) -> 209.67 | F54: =IFERROR(Datasheet!E63,0) -> 140.24 | G54: =IFERROR(Datasheet!F63,0) -> 182.98 | H54: =IFERROR(Datasheet!G63,0) -> 426.43 | I54: =IFERROR(Datasheet!H63,0) -> 1019.59 | J54: =IFERROR(Datasheet!I63,0) -> 2698.37 | ... L54: =IFERROR(Datasheet!K63,0) -> 1848.67 | M54: =L54 -> 1848.67
B55: Investments | C55: =IFERROR(Datasheet!B64,0) -> 2651.99 | D55: =IFERROR(Datasheet!C64,0) -> 2140.7 | E55: =IFERROR(Datasheet!D64,0) -> 2568.58 | F55: =IFERROR(Datasheet!E64,0) -> 2018.85 | G55: =IFERROR(Datasheet!F64,0) -> 4736.8 | H55: =IFERROR(Datasheet!G64,0) -> 3247.53 | I55: =IFERROR(Datasheet!H64,0) -> 4261.71 | J55: =IFERROR(Datasheet!I64,0) -> 4587.92 | ... L55: =IFERROR(Datasheet!K64,0) -> 7061.74 | M55: =L55 -> 7061.74
B56: Other Assets | C56: =IFERROR(Datasheet!B65-SUM(Datasheet!B67:B69),0) -> 1317.17 | D56: =IFERROR(Datasheet!C65-SUM(Datasheet!C67:C69),0) -> 1691.84 | E56: =IFERROR(Datasheet!D65-SUM(Datasheet!D67:D69),0) -> 1471.96 | F56: =IFERROR(Datasheet!E65-SUM(Datasheet!E67:E69),0) -> 1738.71 | G56: =IFERROR(Datasheet!F65-SUM(Datasheet!F67:F69),0) -> 2565.52 | H56: =IFERROR(Datasheet!G65-SUM(Datasheet!G67:G69),0) -> 2876.66 | I56: =IFERROR(Datasheet!H65-SUM(Datasheet!H67:H69),0) -> 3036.17 | J56: =IFERROR(Datasheet!I65-SUM(Datasheet!I67:I69),0) -> 3571.39 | ... L56: =IFERROR(Datasheet!K65-SUM(Datasheet!K67:K69),0) -> 4688.89 | M56: =L56 -> 4688.89
B57: Total Non Current Assets | C57: =SUM(C53:C56) -> 7530.44 | D57: =SUM(D53:D56) -> 8969.89 | E57: =SUM(E53:E56) -> 10746.77 | F57: =SUM(F53:F56) -> 10170.11 | G57: =SUM(G53:G56) -> 13343.82 | H57: =SUM(H53:H56) -> 12069.68 | I57: =SUM(I53:I56) -> 14087.93 | J57: =SUM(J53:J56) -> 18004.3 | ... L57: =SUM(L53:L56) -> 23239.58 | M57: =L57 -> 23239.58
...

Sheet Ratio Analysis
B2: ="Ratio Analysis"&" - "&Datasheet!$B$1 -> Ratio Analysis - ASIAN PAINTS LTD
B3: Years | C3: 42825 | D3: 43190 | E3: 43555 | F3: 43921 | G3: 44286 | H3: 44651 | I3: 45016 | J3: 45382 | K3: 45747 | L3: 46112 | M3: Trend | N3: Mean | O3: Median
B5: Sales Growth | C5: =IFERROR(HistoricalFS!C7,0) -> - | D5: =IFERROR(HistoricalFS!D7,0) -> 0.11702039 | E5: =IFERROR(HistoricalFS!E7,0) -> 0.14357472 | F5: =IFERROR(HistoricalFS!F7,0) -> 0.050473671 | G5: =IFERROR(HistoricalFS!G7,0) -> 0.074292288 | H5: =IFERROR(HistoricalFS!H7,0) -> 0.34028285 | I5: =IFERROR(HistoricalFS!I7,0) -> 0.18512278 | J5: =IFERROR(HistoricalFS!J7,0) -> 0.029173127 | ... L5: =IFERROR(HistoricalFS!L7,0) -> 0.049487961 | N5: =IFERROR(AVERAGE(D5:L5),0) -> 0.10496194 | O5: =IFERROR(MEDIAN(D5:L5),0) -> 0.074292288
B6: EBITDA Growth | C6: - | D6: =IFERROR(HistoricalFS!D18/HistoricalFS!C18-1,0) -> 0.070229411 | E6: =IFERROR(HistoricalFS!E18/HistoricalFS!D18-1,0) -> 0.17507124 | F6: =IFERROR(HistoricalFS!F18/HistoricalFS!E18-1,0) -> 0.10540141 | G6: =IFERROR(HistoricalFS!G18/HistoricalFS!F18-1,0) -> 0.16671512 | H6: =IFERROR(HistoricalFS!H18/HistoricalFS!G18-1,0) -> -0.010707225 | I6: =IFERROR(HistoricalFS!I18/HistoricalFS!H18-1,0) -> 0.30315325 | J6: =IFERROR(HistoricalFS!J18/HistoricalFS!I18-1,0) -> 0.21168912 | K6: =IFERROR(HistoricalFS!K18/HistoricalFS!J18-1,0) -> -0.20814425 | L6: =IFERROR(HistoricalFS!L18/HistoricalFS!K18-1,0) -> 0.11546716 | N6: =IFERROR(AVERAGE(D6:L6),0) -> 0.10320836 | O6: =IFERROR(MEDIAN(D6:L6),0) -> 0.11546716
B7: EBIT Growth | C7: - | D7: =IFERROR(SUM(HistoricalFS!D27,HistoricalFS!D21)/SUM(HistoricalFS!C27,HistoricalFS!C21)-1,0) -> 0.069414096 | E7: =IFERROR(SUM(HistoricalFS!E27,HistoricalFS!E21)/SUM(HistoricalFS!D27,HistoricalFS!D21)-1,0) -> 0.10524206 | F7: =IFERROR(SUM(HistoricalFS!F27,HistoricalFS!F21)/SUM(HistoricalFS!E27,HistoricalFS!E21)-1,0) -> 0.075878198 | G7: =IFERROR(SUM(HistoricalFS!G27,HistoricalFS!G21)/SUM(HistoricalFS!F27,HistoricalFS!F21)-1,0) -> 0.20201285 | H7: =IFERROR(SUM(HistoricalFS!H27,HistoricalFS!H21)/SUM(HistoricalFS!G27,HistoricalFS!G21)-1,0) -> -0.018964995 | I7: =IFERROR(SUM(HistoricalFS!I27,HistoricalFS!I21)/SUM(HistoricalFS!H27,HistoricalFS!H21)-1,0) -> 0.35477334 | J7: =IFERROR(SUM(HistoricalFS!J27,HistoricalFS!J21)/SUM(HistoricalFS!I27,HistoricalFS!I21)-1,0) -> 0.24624293 | K7: =IFERROR(SUM(HistoricalFS!K27,HistoricalFS!K21)/SUM(HistoricalFS!J27,HistoricalFS!J21)-1,0) -> -0.26026667 | L7: =IFERROR(SUM(HistoricalFS!L27,HistoricalFS!L21)/SUM(HistoricalFS!K27,HistoricalFS!K21)-1,0) -> 0.098598959 | N7: =IFERROR(AVERAGE(D7:L7),0) -> 0.096992308 | O7: =IFERROR(MEDIAN(D7:L7),0) -> 0.098598959
B8: Net Profit Growth | C8: - | D8: =IFERROR(HistoricalFS!D33/HistoricalFS!C33-1,0) -> 0.049310335 | E8: =IFERROR(HistoricalFS!E33/HistoricalFS!D33-1,0) -> 0.098324352 | F8: =IFERROR(HistoricalFS!F33/HistoricalFS!E33-1,0) -> 0.25323249 | G8: =IFERROR(HistoricalFS!G33/HistoricalFS!F33-1,0) -> 0.18605332 | H8: =IFERROR(HistoricalFS!H33/HistoricalFS!G33-1,0) -> -0.029971131 | I8: =IFERROR(HistoricalFS!I33/HistoricalFS!H33-1,0) -> 0.34957493 | J8: =IFERROR(HistoricalFS!J33/HistoricalFS!I33-1,0) -> 0.25847333 | K8: =IFERROR(HistoricalFS!K33/HistoricalFS!J33-1,0) -> -0.29075755 | L8: =IFERROR(HistoricalFS!L33/HistoricalFS!K33-1,0) -> 0.091451381 | N8: =IFERROR(AVERAGE(D8:L8),0) -> 0.10729905 | O8: =IFERROR(MEDIAN(D8:L8),0) -> 0.098324352
B9: Dividend Growth | C9: - | D9: =IFERROR(HistoricalFS!D41/HistoricalFS!C41-1,0) -> -0.15534727 | E9: =IFERROR(HistoricalFS!E41/HistoricalFS!D41-1,0) -> 0.20690234 | F9: =IFERROR(HistoricalFS!F41/HistoricalFS!E41-1,0) -> 0.14285714 | G9: =IFERROR(HistoricalFS!G41/HistoricalFS!F41-1,0) -> 0.48749826 | H9: =IFERROR(HistoricalFS!H41/HistoricalFS!G41-1,0) -> 0.072831553 | I9: =IFERROR(HistoricalFS!I41/HistoricalFS!H41-1,0) -> 0.33942522 | J9: =IFERROR(HistoricalFS!J41/HistoricalFS!I41-1,0) -> 0.29824618 | K9: =IFERROR(HistoricalFS!K41/HistoricalFS!J41-1,0) -> -0.25525494 | L9: =IFERROR(HistoricalFS!L41/HistoricalFS!K41-1,0) -> 0.1088691 | N9: =IFERROR(AVERAGE(D9:L9),0) -> 0.13844751 | O9: =IFERROR(MEDIAN(D9:L9),0) -> 0.14285714
B11: Gross Margins | C11: =IFERROR(HistoricalFS!C13,0) -> 0.35382642 | D11: =IFERROR(HistoricalFS!D13,0) -> 0.33465264 | E11: =IFERROR(HistoricalFS!E13,0) -> 0.32922439 | F11: =IFERROR(HistoricalFS!F13,0) -> 0.34897545 | G11: =IFERROR(HistoricalFS!G13,0) -> 0.35360357 | H11: =IFERROR(HistoricalFS!H13,0) -> 0.2924514 | I11: =IFERROR(HistoricalFS!I13,0) -> 0.31088224 | J11: =IFERROR(HistoricalFS!J13,0) -> 0.35173503 | ... L11: =IFERROR(HistoricalFS!L13,0) -> 0.33987372 | N11: =IFERROR(AVERAGE(C11:L11),0) -> 0.33445021 | O11: =IFERROR(MEDIAN(C11:L11),0) -> 0.33726318
B12: EBITDA Margin | C12: =IFERROR(HistoricalFS!C19,0) -> 0.19876258 | D12: =IFERROR(HistoricalFS!D19,0) -> 0.19043659 | E12: =IFERROR(HistoricalFS!E19,0) -> 0.19568163 | F12: =IFERROR(HistoricalFS!F19,0) -> 0.20591354 | G12: =IFERROR(HistoricalFS!G19,0) -> 0.22362856 | H12: =IFERROR(HistoricalFS!H19,0) -> 0.16506525 | I12: =IFERROR(HistoricalFS!I19,0) -> 0.18150467 | J12: =IFERROR(HistoricalFS!J19,0) -> 0.21369313 | ... L12: =IFERROR(HistoricalFS!L19,0) -> 0.18828172 | N12: =IFERROR(AVERAGE(C12:L12),0) -> 0.19401126 | O12: =IFERROR(MEDIAN(C12:L12),0) -> 0.19305911
B13: EBIT Margin | C13: =IFERROR(SUM(HistoricalFS!C27,HistoricalFS!C21)/HistoricalFS!C6,0) -> 0.17653511 | D13: =IFERROR(SUM(HistoricalFS!D27,HistoricalFS!D21)/HistoricalFS!D6,0) -> 0.16901136 | E13: =IFERROR(SUM(HistoricalFS!E27,HistoricalFS!E21)/HistoricalFS!E6,0) -> 0.16334609 | F13: =IFERROR(SUM(HistoricalFS!F27,HistoricalFS!F21)/HistoricalFS!F6,0) -> 0.16729643 | G13: =IFERROR(SUM(HistoricalFS!G27,HistoricalFS!G21)/HistoricalFS!G6,0) -> 0.18718599 | H13: =IFERROR(SUM(HistoricalFS!H27,HistoricalFS!H21)/HistoricalFS!H6,0) -> 0.13701287 | I13: =IFERROR(SUM(HistoricalFS!I27,HistoricalFS!I21)/HistoricalFS!I6,0) -> 0.15662629 | J13: =IFERROR(SUM(HistoricalFS!J27,HistoricalFS!J21)/HistoricalFS!J6,0) -> 0.18966139 | ... L13: =IFERROR(SUM(HistoricalFS!L27,HistoricalFS!L21)/HistoricalFS!L6,0) -> 0.15374749 | N13: =IFERROR(AVERAGE(C13:L13),0) -> 0.16472975 | O13: =IFERROR(MEDIAN(C13:L13),0) -> 0.16532126
B14: EBT Margin | C14: =IFERROR(HistoricalFS!C28,0) -> 0.17405668 | D14: =IFERROR(HistoricalFS!D28,0) -> 0.1665465 | E14: =IFERROR(HistoricalFS!E28,0) -> 0.15760444 | F14: =IFERROR(HistoricalFS!F28,0) -> 0.16223341 | G14: =IFERROR(HistoricalFS!G28,0) -> 0.18296589 | H14: =IFERROR(HistoricalFS!H28,0) -> 0.13373432 | I14: =IFERROR(HistoricalFS!I28,0) -> 0.15243795 | J14: =IFERROR(HistoricalFS!J28,0) -> 0.1838811 | ... L14: =IFERROR(HistoricalFS!L28,0) -> 0.14825591 | N14: =IFERROR(AVERAGE(C14:L14),0) -> 0.1601895 | O14: =IFERROR(MEDIAN(C14:L14),0) -> 0.15991893
B15: Net Profit Margin | C15: =IFERROR(HistoricalFS!C34,0) -> 0.1114295 | D15: =IFERROR(HistoricalFS!D34,0) -> 0.10467501 | E15: =IFERROR(HistoricalFS!E34,0) -> 0.1005331 | F15: =IFERROR(HistoricalFS!F34,0) -> 0.11993766 | G15: =IFERROR(HistoricalFS!G34,0) -> 0.13241504 | H15: =IFERROR(HistoricalFS!H34,0) -> 0.095835303 | I15: =IFERROR(HistoricalFS!I34,0) -> 0.10913377 | J15: =IFERROR(HistoricalFS!J34,0) -> 0.13344882 | ... L15: =IFERROR(HistoricalFS!L34,0) -> 0.1030454 | N15: =IFERROR(AVERAGE(C15:L15),0) -> 0.11095372 | O15: =IFERROR(MEDIAN(C15:L15),0) -> 0.10690439
B17: Sales Expense % Sales | C17: =IFERROR(HistoricalFS!C16,0) -> 0.15506384 | D17: =IFERROR(HistoricalFS!D16,0) -> 0.14421604 | E17: =IFERROR(HistoricalFS!E16,0) -> 0.13354276 | F17: =IFERROR(HistoricalFS!F16,0) -> 0.14306191 | G17: =IFERROR(HistoricalFS!G16,0) -> 0.12997501 | H17: =IFERROR(HistoricalFS!H16,0) -> 0.12738615 | I17: =IFERROR(HistoricalFS!I16,0) -> 0.12937757 | J17: =IFERROR(HistoricalFS!J16,0) -> 0.1380419 | ... L17: =IFERROR(HistoricalFS!L16,0) -> 0.151592 | N17: =IFERROR(AVERAGE(C17:L17),0) -> 0.14043895 | O17: =IFERROR(MEDIAN(C17:L17),0) -> 0.1405519
B18: Depreciation % Gross Block | C18: =IFERROR(HistoricalFS!C25,0) -> 0.085536536 | D18: =IFERROR(HistoricalFS!D25,0) -> 0.07661424 | E18: =IFERROR(HistoricalFS!E25,0) -> 0.076420587 | F18: =IFERROR(HistoricalFS!F25,0) -> 0.094240522 | G18: =IFERROR(HistoricalFS!G25,0) -> 0.094288608 | H18: =IFERROR(HistoricalFS!H25,0) -> 0.095614898 | I18: =IFERROR(HistoricalFS!I25,0) -> 0.088675072 | J18: =IFERROR(HistoricalFS!J25,0) -> 0.073395285 | ... L18: =IFERROR(HistoricalFS!L25,0) -> 0.08023309 | N18: =IFERROR(AVERAGE(C18:L18),0) -> 0.083781407 | O18: =IFERROR(MEDIAN(C18:L18),0) -> 0.082884813
B19: Operating Income % Sales | C19: =IFERROR(SUM(HistoricalFS!C27,HistoricalFS!C21)/HistoricalFS!C6,0) -> 0.17653511 | D19: =IFERROR(SUM(HistoricalFS!D27,HistoricalFS!D21)/HistoricalFS!D6,0) -> 0.16901136 | E19: =IFERROR(SUM(HistoricalFS!E27,HistoricalFS!E21)/HistoricalFS!E6,0) -> 0.16334609 | F19: =IFERROR(SUM(HistoricalFS!F27,HistoricalFS!F21)/HistoricalFS!F6,0) -> 0.16729643 | G19: =IFERROR(SUM(HistoricalFS!G27,HistoricalFS!G21)/HistoricalFS!G6,0) -> 0.18718599 | H19: =IFERROR(SUM(HistoricalFS!H27,HistoricalFS!H21)/HistoricalFS!H6,0) -> 0.13701287 | I19: =IFERROR(SUM(HistoricalFS!I27,HistoricalFS!I21)/HistoricalFS!I6,0) -> 0.15662629 | J19: =IFERROR(SUM(HistoricalFS!J27,HistoricalFS!J21)/HistoricalFS!J6,0) -> 0.18966139 | ... L19: =IFERROR(SUM(HistoricalFS!L27,HistoricalFS!L21)/HistoricalFS!L6,0) -> 0.15374749 | N19: =IFERROR(AVERAGE(C19:L19),0) -> 0.16472975 | O19: =IFERROR(MEDIAN(C19:L19),0) -> 0.16532126
B21: Return on Capital Employed | C21: =IFERROR((HistoricalFS!C18-HistoricalFS!C24)/SUM(HistoricalFS!C47:C49),0) -> 0.32568534 | D21: =IFERROR((HistoricalFS!D18-HistoricalFS!D24)/SUM(HistoricalFS!D47:D49),0) -> 0.31793919 | E21: =IFERROR((HistoricalFS!E18-HistoricalFS!E24)/SUM(HistoricalFS!E47:E49),0) -> 0.29126565 | F21: =IFERROR((HistoricalFS!F18-HistoricalFS!F24)/SUM(HistoricalFS!F47:F49),0) -> 0.30059314 | G21: =IFERROR((HistoricalFS!G18-HistoricalFS!G24)/SUM(HistoricalFS!G47:G49),0) -> 0.29241025 | H21: =IFERROR((HistoricalFS!H18-HistoricalFS!H24)/SUM(HistoricalFS!H47:H49),0) -> 0.25893857 | I21: =IFERROR((HistoricalFS!I18-HistoricalFS!I24)/SUM(HistoricalFS!I47:I49),0) -> 0.30135929 | J21: =IFERROR((HistoricalFS!J18-HistoricalFS!J24)/SUM(HistoricalFS!J47:J49),0) -> 0.31750609 | ... L21: =IFERROR((HistoricalFS!L18-HistoricalFS!L24)/SUM(HistoricalFS!L47:L49),0) -> 0.21623587 | N21: =IFERROR(AVERAGE(C21:L21),0) -> 0.28515252 | O21: =IFERROR(MEDIAN(C21:L21),0) -> 0.2965017
B22: Retained Earnings % | C22: =IFERROR(HistoricalFS!C44,0) -> 0.41133852 | D22: =IFERROR(HistoricalFS!D44,0) -> 0.52615112 | E22: =IFERROR(HistoricalFS!E44,0) -> 0.47930744 | F22: =IFERROR(HistoricalFS!F44,0) -> 0.52516614 | G22: =IFERROR(HistoricalFS!G44,0) -> 0.40448332 | H22: =IFERROR(HistoricalFS!H44,0) -> 0.34137106 | I22: =IFERROR(HistoricalFS!I44,0) -> 0.34632439 | J22: =IFERROR(HistoricalFS!J44,0) -> 0.3256656 | ... L22: =IFERROR(HistoricalFS!L44,0) -> 0.28061046 | N22: =IFERROR(AVERAGE(C22:L22),0) -> 0.39323284 | O22: =IFERROR(MEDIAN(C22:L22),0) -> 0.37540386
B23: Return on Equity % | C23: =IFERROR(HistoricalFS!C33/SUM(HistoricalFS!C47:C48),0) -> 0.22072255 | D23: =IFERROR(HistoricalFS!D33/SUM(HistoricalFS!D47:D48),0) -> 0.20940093 | E23: =IFERROR(HistoricalFS!E33/SUM(HistoricalFS!E47:E48),0) -> 0.20424051 | F23: =IFERROR(HistoricalFS!F33/SUM(HistoricalFS!F47:F48),0) -> 0.23929434 | G23: =IFERROR(HistoricalFS!G33/SUM(HistoricalFS!G47:G48),0) -> 0.22450686 | H23: =IFERROR(HistoricalFS!H33/SUM(HistoricalFS!H47:H48),0) -> 0.20192723 | I23: =IFERROR(HistoricalFS!I33/SUM(HistoricalFS!I47:I48),0) -> 0.23535617 | J23: =IFERROR(HistoricalFS!J33/SUM(HistoricalFS!J47:J48),0) -> 0.25291831 | ... L23: =IFERROR(HistoricalFS!L33/SUM(HistoricalFS!L47:L48),0) -> 0.17156983 | N23: =IFERROR(AVERAGE(C23:L23),0) -> 0.2133108 | O23: =IFERROR(MEDIAN(C23:L23),0) -> 0.21506174
B24: Self Sustained Growth Rate | C24: =IFERROR(C22*C23,0) -> 0.090791687 | D24: =IFERROR(D22*D23,0) -> 0.11017654 | E24: =IFERROR(E22*E23,0) -> 0.097893998 | F24: =IFERROR(F22*F23,0) -> 0.12566929 | G24: =IFERROR(G22*G23,0) -> 0.090809282 | H24: =IFERROR(H22*H23,0) -> 0.068932112 | I24: =IFERROR(I22*I23,0) -> 0.081509583 | J24: =IFERROR(J22*J23,0) -> 0.082366793 | ... L24: =IFERROR(L22*L23,0) -> 0.048144289 | N24: =IFERROR(AVERAGE(C24:L24),0) -> 0.084684406 | O24: =IFERROR(MEDIAN(C24:L24),0) -> 0.08657924
B25: Interest Coverage Ratio | C25: =IFERROR(SUM(HistoricalFS!C27,HistoricalFS!C21)/HistoricalFS!C21,0) -> 71.22877 | D25: =IFERROR(SUM(HistoricalFS!D27,HistoricalFS!D21)/HistoricalFS!D21,0) -> 68.568604 | E25: =IFERROR(SUM(HistoricalFS!E27,HistoricalFS!E21)/HistoricalFS!E21,0) -> 28.449353 | F25: =IFERROR(SUM(HistoricalFS!F27,HistoricalFS!F21)/HistoricalFS!F21,0) -> 33.042803 | G25: =IFERROR(SUM(HistoricalFS!G27,HistoricalFS!G21)/HistoricalFS!G21,0) -> 44.355888 | H25: =IFERROR(SUM(HistoricalFS!H27,HistoricalFS!H21)/HistoricalFS!H21,0) -> 41.790693 | I25: =IFERROR(SUM(HistoricalFS!I27,HistoricalFS!I21)/HistoricalFS!I21,0) -> 37.395777 | J25: =IFERROR(SUM(HistoricalFS!J27,HistoricalFS!J21)/HistoricalFS!J21,0) -> 32.811717 | ... L25: =IFERROR(SUM(HistoricalFS!L27,HistoricalFS!L21)/HistoricalFS!L21,0) -> 27.99693 | N25: =IFERROR(AVERAGE(C25:L25),0) -> 40.757635 | O25: =IFERROR(MEDIAN(C25:L25),0) -> 35.21929
B27: Debtor Turnover Ratio | D27: =IFERROR(HistoricalFS!D6/AVERAGE('Raw FS'!E32:F32),0) -> 10.588137 | E27: =IFERROR(HistoricalFS!E6/AVERAGE('Raw FS'!F32:G32),0) -> 10.577312 | F27: =IFERROR(HistoricalFS!F6/AVERAGE('Raw FS'!G32:H32),0) -> 10.919098 | G27: =IFERROR(HistoricalFS!G6/AVERAGE('Raw FS'!H32:I32),0) -> 9.8761838 | H27: =IFERROR(HistoricalFS!H6/AVERAGE('Raw FS'!I32:J32),0) -> 8.9915897 | I27: =IFERROR(HistoricalFS!I6/AVERAGE('Raw FS'!J32:K32),0) -> 8.1073319 | J27: =IFERROR(HistoricalFS!J6/AVERAGE('Raw FS'!K32:L32),0) -> 7.4521793 | K27: =IFERROR(HistoricalFS!K6/AVERAGE('Raw FS'!L32:M32),0) -> 7.3683842 | L27: =IFERROR(HistoricalFS!L6/AVERAGE('Raw FS'!M32:N32),0) -> 8.1092844 | N27: =IFERROR(AVERAGE(D27:L27),0) -> 9.1099444 | O27: =IFERROR(MEDIAN(D27:L27),0) -> 8.9915897
B28: Creditor Turnover ratio | D28: =IFERROR(HistoricalFS!D9/AVERAGE('Raw FS'!E13:F13),0) -> 5.4833064 | E28: =IFERROR(HistoricalFS!E9/AVERAGE('Raw FS'!F13:G13),0) -> 5.6679007 | F28: =IFERROR(HistoricalFS!F9/AVERAGE('Raw FS'!G13:H13),0) -> 5.8079982 | G28: =IFERROR(HistoricalFS!G9/AVERAGE('Raw FS'!H13:I13),0) -> 5.0888579 | H28: =IFERROR(HistoricalFS!H9/AVERAGE('Raw FS'!I13:J13),0) -> 5.4595174 | I28: =IFERROR(HistoricalFS!I9/AVERAGE('Raw FS'!J13:K13),0) -> 6.094807 | J28: =IFERROR(HistoricalFS!J9/AVERAGE('Raw FS'!K13:L13),0) -> 6.1639405 | K28: =IFERROR(HistoricalFS!K9/AVERAGE('Raw FS'!L13:M13),0) -> 5.922977 | L28: =IFERROR(HistoricalFS!L9/AVERAGE('Raw FS'!M13:N13),0) -> 6.092499 | N28: =IFERROR(AVERAGE(D28:L28),0) -> 5.7535338 | O28: =IFERROR(MEDIAN(D28:L28),0) -> 5.8079982
B29: Inventory Turnover Ratio | D29: =IFERROR(HistoricalFS!D9/AVERAGE(HistoricalFS!C60:D60),0) -> 4.236004 | E29: =IFERROR(HistoricalFS!E9/AVERAGE(HistoricalFS!D60:E60),0) -> 4.4440194 | F29: =IFERROR(HistoricalFS!F9/AVERAGE(HistoricalFS!E60:F60),0) -> 4.0240624 | G29: =IFERROR(HistoricalFS!G9/AVERAGE(HistoricalFS!F60:G60),0) -> 3.9049164 | H29: =IFERROR(HistoricalFS!H9/AVERAGE(HistoricalFS!G60:H60),0) -> 4.1381509 | I29: =IFERROR(HistoricalFS!I9/AVERAGE(HistoricalFS!H60:I60),0) -> 3.8446183 | J29: =IFERROR(HistoricalFS!J9/AVERAGE(HistoricalFS!I60:J60),0) -> 3.7926315 | K29: =IFERROR(HistoricalFS!K9/AVERAGE(HistoricalFS!J60:K60),0) -> 3.5975394 | L29: =IFERROR(HistoricalFS!L9/AVERAGE(HistoricalFS!K60:L60),0) -> 3.7695106 | N29: =IFERROR(AVERAGE(D29:L29),0) -> 3.9723837 | O29: =IFERROR(MEDIAN(D29:L29),0) -> 3.9049164
B30: Fixed Asset Turnover ratio | D30: =IFERROR(HistoricalFS!D6/AVERAGE(HistoricalFS!C53:D53),0) -> 4.7824326 | E30: =IFERROR(HistoricalFS!E6/AVERAGE(HistoricalFS!D53:E53),0) -> 3.7619525 | F30: =IFERROR(HistoricalFS!F6/AVERAGE(HistoricalFS!E53:F53),0) -> 3.1657069 | G30: =IFERROR(HistoricalFS!G6/AVERAGE(HistoricalFS!F53:G53),0) -> 3.5797699 | H30: =IFERROR(HistoricalFS!H6/AVERAGE(HistoricalFS!G53:H53),0) -> 5.1155483 | I30: =IFERROR(HistoricalFS!I6/AVERAGE(HistoricalFS!H53:I53),0) -> 6.1098417 | J30: =IFERROR(HistoricalFS!J6/AVERAGE(HistoricalFS!I53:J53),0) -> 5.4957823 | K30: =IFERROR(HistoricalFS!K6/AVERAGE(HistoricalFS!J53:K53),0) -> 4.1432395 | L30: =IFERROR(HistoricalFS!L6/AVERAGE(HistoricalFS!K53:L53),0) -> 3.7733641 | N30: =IFERROR(AVERAGE(D30:L30),0) -> 4.4364042 | O30: =IFERROR(MEDIAN(D30:L30),0) -> 4.1432395
B31: Capital Turonver Ratio | D31: =IFERROR(HistoricalFS!D6/AVERAGE(SUM(HistoricalFS!D47:D48),SUM(HistoricalFS!C47:C48)),0) -> 2.1012144 | E31: =IFERROR(HistoricalFS!E6/AVERAGE(SUM(HistoricalFS!E47:E48),SUM(HistoricalFS!D47:D48)),0) -> 2.1520459 | F31: =IFERROR(HistoricalFS!F6/AVERAGE(SUM(HistoricalFS!F47:F48),SUM(HistoricalFS!E47:E48)),0) -> 2.0622977 | G31: =IFERROR(HistoricalFS!G6/AVERAGE(SUM(HistoricalFS!G47:G48),SUM(HistoricalFS!F47:F48)),0) -> 1.8933 | H31: =IFERROR(HistoricalFS!H6/AVERAGE(SUM(HistoricalFS!H47:H48),SUM(HistoricalFS!G47:G48)),0) -> 2.1865988 | I31: =IFERROR(HistoricalFS!I6/AVERAGE(SUM(HistoricalFS!I47:I48),SUM(HistoricalFS!H47:H48)),0) -> 2.3143761 | J31: =IFERROR(HistoricalFS!J6/AVERAGE(SUM(HistoricalFS!J47:J48),SUM(HistoricalFS!I47:I48)),0) -> 2.0445961 | K31: =IFERROR(HistoricalFS!K6/AVERAGE(SUM(HistoricalFS!K47:K48),SUM(HistoricalFS!J47:J48)),0) -> 1.7785104 | L31: =IFERROR(HistoricalFS!L6/AVERAGE(SUM(HistoricalFS!L47:L48),SUM(HistoricalFS!K47:K48)),0) -> 1.7455147 | N31: =IFERROR(AVERAGE(D31:L31),0) -> 2.0309394 | O31: =IFERROR(MEDIAN(D31:L31),0) -> 2.0622977
B33: Days taken | C33: 365
B34: Debtor Days | D34: =IFERROR($C$33/D27,0) -> 34.472542 | E34: =IFERROR($C$33/E27,0) -> 34.507823 | F34: =IFERROR($C$33/F27,0) -> 33.42767 | G34: =IFERROR($C$33/G27,0) -> 36.957595 | H34: =IFERROR($C$33/H27,0) -> 40.593489 | I34: =IFERROR($C$33/I27,0) -> 45.020977 | J34: =IFERROR($C$33/J27,0) -> 48.978961 | K34: =IFERROR($C$33/K27,0) -> 49.535962 | L34: =IFERROR($C$33/L27,0) -> 45.010137 | N34: =IFERROR(AVERAGE(D34:L34),0) -> 40.945017 | O34: =IFERROR(MEDIAN(D34:L34),0) -> 40.593489
B35: Payable Days | D35: =IFERROR($C$33/D28,0) -> 66.565677 | E35: =IFERROR($C$33/E28,0) -> 64.39774 | F35: =IFERROR($C$33/F28,0) -> 62.844372 | G35: =IFERROR($C$33/G28,0) -> 71.725328 | H35: =IFERROR($C$33/H28,0) -> 66.855726 | I35: =IFERROR($C$33/I28,0) -> 59.887048 | J35: =IFERROR($C$33/J28,0) -> 59.215367 | K35: =IFERROR($C$33/K28,0) -> 61.624417 | L35: =IFERROR($C$33/L28,0) -> 59.909735 | N35: =IFERROR(AVERAGE(D35:L35),0) -> 63.66949 | O35: =IFERROR(MEDIAN(D35:L35),0) -> 62.844372
B36: Inventory Days | D36: =IFERROR($C$33/D29,0) -> 86.166114 | E36: =IFERROR($C$33/E29,0) -> 82.132855 | F36: =IFERROR($C$33/F29,0) -> 90.704359 | G36: =IFERROR($C$33/G29,0) -> 93.471912 | H36: =IFERROR($C$33/H29,0) -> 88.203646 | I36: =IFERROR($C$33/I29,0) -> 94.937903 | J36: =IFERROR($C$33/J29,0) -> 96.239248 | K36: =IFERROR($C$33/K29,0) -> 101.45823 | L36: =IFERROR($C$33/L29,0) -> 96.829546 | N36: =IFERROR(AVERAGE(D36:L36),0) -> 92.238202 | O36: =IFERROR(MEDIAN(D36:L36),0) -> 93.471912
B37: Cash Conversion Cycle | D37: =IFERROR(ABS(D34+D36-D35),0) -> 54.072979 | E37: =IFERROR(ABS(E34+E36-E35),0) -> 52.242938 | F37: =IFERROR(ABS(F34+F36-F35),0) -> 61.287658 | G37: =IFERROR(ABS(G34+G36-G35),0) -> 58.704179 | H37: =IFERROR(ABS(H34+H36-H35),0) -> 61.94141 | I37: =IFERROR(ABS(I34+I36-I35),0) -> 80.071831 | J37: =IFERROR(ABS(J34+J36-J35),0) -> 86.002842 | K37: =IFERROR(ABS(K34+K36-K35),0) -> 89.369779 | L37: =IFERROR(ABS(L34+L36-L35),0) -> 81.929948 | N37: =IFERROR(AVERAGE(D37:L37),0) -> 69.513729 | O37: =IFERROR(MEDIAN(D37:L37),0) -> 61.94141
B39: CFO/Sales | D39: =IFERROR(HistoricalFS!D77/HistoricalFS!D6,0) -> 0.12559028 | E39: =IFERROR(HistoricalFS!E77/HistoricalFS!E6,0) -> 0.12832554 | F39: =IFERROR(HistoricalFS!F77/HistoricalFS!F6,0) -> 0.15031233 | G39: =IFERROR(HistoricalFS!G77/HistoricalFS!G6,0) -> 0.16966958 | H39: =IFERROR(HistoricalFS!H77/HistoricalFS!H6,0) -> 0.033881671 | I39: =IFERROR(HistoricalFS!I77/HistoricalFS!I6,0) -> 0.12160544 | J39: =IFERROR(HistoricalFS!J77/HistoricalFS!J6,0) -> 0.17196919 | K39: =IFERROR(HistoricalFS!K77/HistoricalFS!K6,0) -> 0.13047984 | L39: =IFERROR(HistoricalFS!L77/HistoricalFS!L6,0) -> 0.19919322 | N39: =IFERROR(AVERAGE(C39:L39),0) -> 0.13678079 | O39: =IFERROR(MEDIAN(C39:L39),0) -> 0.13047984
B40: CFO/Total Assets | C40: =IFERROR(HistoricalFS!C77/HistoricalFS!C64,0) -> 0.12317425 | D40: =IFERROR(HistoricalFS!D77/HistoricalFS!D64,0) -> 0.15352222 | E40: =IFERROR(HistoricalFS!E77/HistoricalFS!E64,0) -> 0.15194931 | F40: =IFERROR(HistoricalFS!F77/HistoricalFS!F64,0) -> 0.18825168 | G40: =IFERROR(HistoricalFS!G77/HistoricalFS!G64,0) -> 0.18098445 | H40: =IFERROR(HistoricalFS!H77/HistoricalFS!H64,0) -> 0.042947188 | I40: =IFERROR(HistoricalFS!I77/HistoricalFS!I64,0) -> 0.16268848 | J40: =IFERROR(HistoricalFS!J77/HistoricalFS!J64,0) -> 0.2041419 | ... L40: =IFERROR(HistoricalFS!L77/HistoricalFS!L64,0) -> 0.20533768 | N40: =IFERROR(AVERAGE(C40:L40),0) -> 0.1558738 | O40: =IFERROR(MEDIAN(C40:L40),0) -> 0.15810535
B41: CFO/Total Debt | C41: =IFERROR(HistoricalFS!C77/HistoricalFS!C49,0) -> 2.7269158 | D41: =IFERROR(HistoricalFS!D77/HistoricalFS!D49,0) -> 3.961157 | E41: =IFERROR(HistoricalFS!E77/HistoricalFS!E49,0) -> 1.8710215 | F41: =IFERROR(HistoricalFS!F77/HistoricalFS!F49,0) -> 2.7161377 | G41: =IFERROR(HistoricalFS!G77/HistoricalFS!G49,0) -> 3.3701698 | H41: =IFERROR(HistoricalFS!H77/HistoricalFS!H49,0) -> 0.62134503 | I41: =IFERROR(HistoricalFS!I77/HistoricalFS!I49,0) -> 2.170111 | J41: =IFERROR(HistoricalFS!J77/HistoricalFS!J49,0) -> 2.4668806 | ... L41: =IFERROR(HistoricalFS!L77/HistoricalFS!L49,0) -> 1.8040535 | N41: =IFERROR(AVERAGE(C41:L41),0) -> 2.3639425 | O41: =IFERROR(MEDIAN(C41:L41),0) -> 2.3184958

Sheet Forecast(Explicit)
B2: ="Forecast"&" - "&Datasheet!$B$1 -> Forecast - ASIAN PAINTS LTD
B4: Section 1: Revenue
B5: Revenue Growth | C5: 0.06 | D5: 0.06 | E5: 0.07 | F5: 0.07 | G5: 0.07
B6: Revenue | C6: =HistoricalFS!$L$6*(1+'Forecast(Explicit)'!C5) -> 37718.552 | D6: =C6*(1+D5) -> 39981.666 | E6: =D6*(1+E5) -> 42780.382 | F6: =E6*(1+F5) -> 45775.009 | G6: =F6*(1+G5) -> 48979.26
B9: Section 2: Gross Margin & COGS
B10: Years | C10: 2027 | D10: =C10+1 -> 2028 | E10: =D10+1 -> 2029 | F10: =E10+1 -> 2030 | G10: =F10+1 -> 2031
B11: Gross Margin | C11: 0.35 | D11: 0.35 | E11: 0.36 | F11: 0.36 | G11: 0.36
B12: Gross Profit | C12: =C6*C11 -> 13201.493 | D12: =D6*D11 -> 13993.583 | E12: =E6*E11 -> 15400.938 | F12: =F6*F11 -> 16479.003 | G12: =G6*G11 -> 17632.533
B14: COGS | C14: =C6-C12 -> 24517.059 | D14: =D6-D12 -> 25988.083 | E14: =E6-E12 -> 27379.445 | F14: =F6-F12 -> 29296.006 | G14: =G6-G12 -> 31346.726
B17: Section 3 : Operating Expenses
B18: Years | C18: 2027 | D18: =C18+1 -> 2028 | E18: =D18+1 -> 2029 | F18: =E18+1 -> 2030 | G18: =F18+1 -> 2031
B19: Other operating Expense | C19: =C6*$H$19 -> 5657.7829 | D19: =D6*$H$19 -> 5997.2498 | E19: =E6*$H$19 -> 6417.0573 | F19: =F6*$H$19 -> 6866.2513 | G19: =G6*$H$19 -> 7346.8889 | H19: 0.15
B20: Total Forecast of Op Exp as % Sales | C20: =SUM(C19) -> 5657.7829 | D20: =SUM(D19) -> 5997.2498 | E20: =SUM(E19) -> 6417.0573 | F20: =SUM(F19) -> 6866.2513 | G20: =SUM(G19) -> 7346.8889
B23: Section 4 : EBITDA
B24: Years | C24: 2027 | D24: =C24+1 -> 2028 | E24: =D24+1 -> 2029 | F24: =E24+1 -> 2030 | G24: =F24+1 -> 2031
B25: EBIDTA Margin | C25: =C26/C6 -> 0.2 | D25: =D26/D6 -> 0.2 | E25: =E26/E6 -> 0.21 | F25: =F26/F6 -> 0.21 | G25: =G26/G6 -> 0.21
B26: EBITDA Amount | C26: =C6-C14-C20 -> 7543.7105 | D26: =D6-D14-D20 -> 7996.3331 | E26: =E6-E14-E20 -> 8983.8802 | F26: =F6-F14-F20 -> 9612.7519 | G26: =G6-G14-G20 -> 10285.644
B28: Section 5 : Depreciation
B29: Years | C29: 2027 | D29: =C29+1 -> 2028 | E29: =D29+1 -> 2029 | F29: =E29+1 -> 2030 | G29: =F29+1 -> 2031
B30: Depreciation | C30: 0.08 | D30: 0.08 | E30: 0.08 | F30: 0.08 | G30: 0.08
B31: Depreciation Amount | C31: ='PPE Schedule'!H10 -> 1346.0595 | D31: ='PPE Schedule'!I10 -> 1435.9657 | E31: ='PPE Schedule'!J10 -> 1592.6433 | F31: ='PPE Schedule'!K10 -> 1760.9217 | G31: ='PPE Schedule'!L10 -> 1916.0314
B33: Section 6 : Interest
B34: Years | C34: 2027 | D34: =C34+1 -> 2028 | E34: =D34+1 -> 2029 | F34: =E34+1 -> 2030 | G34: =F34+1 -> 2031
B35: Interest | C35: 195.41 | D35: 195.41 | E35: 195.41 | F35: 195.41 | G35: 195.41
B37: Section 7: Capital Expenditure
B38: Years | C38: 2027 | D38: =C38+1 -> 2028 | E38: =D38+1 -> 2029 | F38: =E38+1 -> 2030 | G38: =F38+1 -> 2031
B39: Capex | C39: =$H$39*C6 -> 1659.6163 | D39: =$H$39*D6 -> 1759.1933 | E39: =$H$39*E6 -> 1882.3368 | F39: =$H$39*F6 -> 2014.1004 | G39: =$H$39*G6 -> 2155.0874 | H39: 0.044
B40: Capex | C40: ='PPE Schedule'!C16 -> 600 | D40: ='PPE Schedule'!D16 -> 1000 | E40: ='PPE Schedule'!E16 -> 900 | F40: ='PPE Schedule'!F16 -> 400 | G40: ='PPE Schedule'!G16 -> 0 | H40: Bottom Up
B42: Section 8: Operating Working Capital
B43: Years | C43: 2027 | D43: =C43+1 -> 2028 | E43: =D43+1 -> 2029 | F43: =E43+1 -> 2030 | G43: =F43+1 -> 2031
B44: Other Current Liabilities | C44: =$H$44*C6 -> 4149.0408 | D44: =$H$44*D6 -> 4397.9832 | E44: =$H$44*E6 -> 4705.842 | F44: =$H$44*F6 -> 5035.251 | G44: =$H$44*G6 -> 5387.7185 | H44: 0.11
B45: Trade Payable | C45: =('Ratio Analysis'!$O$35/365)*C14 -> 4221.258 | D45: =('Ratio Analysis'!$O$35/365)*D14 -> 4474.5335 | E45: =('Ratio Analysis'!$O$35/365)*E14 -> 4714.0931 | F45: =('Ratio Analysis'!$O$35/365)*F14 -> 5044.0796 | G45: =('Ratio Analysis'!$O$35/365)*G14 -> 5397.1652 | H45: Based on days
B46: Inventory | C46: =(93/365)*C14 -> 6246.8123 | D46: =(93/365)*D14 -> 6621.621 | E46: =(93/365)*E14 -> 6976.1325 | F46: =(93/365)*F14 -> 7464.4617 | G46: =(93/365)*G14 -> 7986.974 | H46: Based on days
B47: Other Current Assets | C47: =$H$47*C6 -> 5092.0046 | D47: =$H$47*D6 -> 5397.5248 | E47: =$H$47*E6 -> 5775.3516 | F47: =$H$47*F6 -> 6179.6262 | G47: =$H$47*G6 -> 6612.2 | H47: 0.135
B48: Trade Recievable | C48: =(45/365)*'Forecast(Explicit)'!C6 -> 4650.2325 | D48: =(45/365)*'Forecast(Explicit)'!D6 -> 4929.2464 | E48: =(45/365)*'Forecast(Explicit)'!E6 -> 5274.2937 | F48: =(45/365)*'Forecast(Explicit)'!F6 -> 5643.4942 | G48: =(45/365)*'Forecast(Explicit)'!G6 -> 6038.5388 | H48: Based on days
B49: Working Capital | C49: =SUM(C46:C48)-SUM(C44:C45) -> 7618.7506 | D49: =SUM(D46:D48)-SUM(D44:D45) -> 8075.8756 | E49: =SUM(E46:E48)-SUM(E44:E45) -> 8605.8426 | F49: =SUM(F46:F48)-SUM(F44:F45) -> 9208.2515 | G49: =SUM(G46:G48)-SUM(G44:G45) -> 9852.8292
B51: Section 9: Fixed Asset
B52: Years | C52: 2027 | D52: =C52+1 -> 2028 | E52: =D52+1 -> 2029 | F52: =E52+1 -> 2030 | G52: =F52+1 -> 2031
B53: Opening PPE | C53: ='Raw FS'!N26 -> 15316 | D53: =C54 -> 16975.616 | E53: =D54 -> 18734.81 | F53: =E54 -> 20617.146 | G53: =F54 -> 22631.247
B54: Closing Gross PPE | C54: =C53+C39 -> 16975.616 | D54: =D53+D39 -> 18734.81 | E54: =E53+E39 -> 20617.146 | F54: =F53+F39 -> 22631.247 | G54: =G53+G39 -> 24786.334
...

Sheet WACC
B2: ="Weighted Average Cost of Capital "&" - "&Datasheet!$B$1 -> Weighted Average Cost of Capital - ASIAN PAINTS LTD
B3: All Figures in INR unless stated otherwise
B5: Peer Comps
H6: Debt/ | I6: Debt/ | J6: Levered | K6: Unlevered
B7: Name of the Comp | D7: Country | E7: Total Debt | F7: Total Equity | G7: Tax Rate1 | H7: Equity | I7: Capital | J7: Beta2 | K7: Beta3
B9: Berger Paints | D9: India | E9: 635.13 | F9: 57863.35 | G9: 0.25 | H9: =E9/F9 -> 0.010976378 | I9: =IFERROR(E9/SUM(E9,F9),0) -> 0.010857205 | J9: =Beta!L33 -> 0.9394496 | K9: =J9/(1+(1-G9)*H9) -> 0.93177894
B10: kansai Nerolac | D10: India | E10: 302.73 | F10: 16046.48 | G10: 0.25 | H10: =E10/F10 -> 0.01886582 | I10: =IFERROR(E10/SUM(E10,F10),0) -> 0.018516491 | J10: =Beta!L23 -> 0.89048014 | K10: =J10/(1+(1-G10)*H10) -> 0.8780562
B11: JSW Dulux | D11: India | E11: 79.1 | F11: 13906.24 | G11: 0.25 | H11: =E11/F11 -> 0.005688094 | I11: =IFERROR(E11/SUM(E11,F11),0) -> 0.0056559226 | J11: =Beta!L43 -> 0.57054979 | K11: =J11/(1+(1-G11)*H11) -> 0.56812613
B12: Indigo Paints | D12: India | E12: 18.37 | F12: 5075.56 | G12: 0.25 | H12: =E12/F12 -> 0.0036193051 | I12: =IFERROR(E12/SUM(E12,F12),0) -> 0.0036062529 | J12: =Beta!L53 -> 0.87909785 | K12: =J12/(1+(1-G12)*H12) -> 0.87671802
B13: Sirca Paints | D13: India | E13: 32.32 | F13: 2236.2 | G13: 0.25 | H13: =E13/F13 -> 0.01445309 | I13: =IFERROR(E13/SUM(E13,F13),0) -> 0.014247174 | J13: =Beta!L63 -> 1.0607296 | K13: =J13/(1+(1-G13)*H13) -> 1.0493548
B15: Cost Of Debt | G15: Average | H15: =AVERAGE(H9:H13) -> 0.010720537 | I15: =AVERAGE(I9:I13) -> 0.010576609 | J15: =AVERAGE(J9:J13) -> 0.8680614 | K15: =AVERAGE(K9:K13) -> 0.86080681
G16: Median | H16: =MEDIAN(H9:H13) -> 0.010976378 | I16: =MEDIAN(I9:I13) -> 0.010857205 | J16: =MEDIAN(J9:J13) -> 0.89048014 | K16: =MEDIAN(K9:K13) -> 0.8780562
B17: Pre Tax Cost of Debt | E17: =K22+0.4% -> 0.0724
B18: Tax Rate | E18: 0.25
B19: Post Tax Cost of Debt | E19: =E17*(1-E18) -> 0.0543
G20: Cost Of Equity
G22: Risk Free Rate | K22: 0.0684
B23: Capital Structure | G23: Equity Risk Premium | K23: ='Market Return'!G5-WACC!K22 -> 0.045045455
G24: Levered Beta4 | K24: =K40 -> 0.8808003
D25: Current | E25: Target | G25: Cost of Equity | K25: =K22+K23*K24 -> 0.10807605
B26: Total Debt | C26: 3928.93 | D26: =IFERROR(C26/$C$28,0) -> 0.014981593 | E26: =I16 -> 0.010857205
